<?xml version='1.0'?>
<robot name="bar"> 

<link name="world"/>
	<joint name="fix_joint" type="fixed">
	<parent link="world"/>
	<child link="base_link"/>
</joint>

<link name="base_link">
	<visual>
              <origin xyz="0 0 0.05" rpy="0 0 0"/>
             	<geometry>
             	 	<box size="0.1 0.1 0.1"/>              
             	</geometry>
              <material name="blue">
              <color rgba="0 0 1 1"/>              
              </material>
	</visual> 
	<collision>
		<origin xyz="0 0 0.25" rpy="0 0 0"/>
         	<geometry>
              		<box size="0.1 0.1 0.1"/>              
        	</geometry>
	</collision>
	<inertial>
 		<mass value="3"/>
		<inertia ixx="0.0225" ixy="0" ixz="0" iyx="0" iyy="0.0225" iyz="0" izx="0" izy="0" izz="0.0225"/>
	</inertial>
</link>

<link name="shaft">
	<visual>
	<origin xyz="0 0.35 0.105" rpy="0 0 0"/>
	<geometry>
	<box size="0.01 0.5 0.01"/>
	</geometry>
	<material name="darkgray">
	<color rgba="0.2 0.2 0.25 1"/>
	</material>
	</visual>
	<collision>	
	<origin xyz="0 0.35 0.105" rpy="0 0 0"/>
	<geometry>
	<box size="0.01 0.5 0.01"/>
	</geometry>
	</collision>
	<inertial>
	<mass value="0.5"/>
	<inertia ixx="0.01" ixy="0.0" ixz="0.0" iyy="0.005" iyz="0.0" izz="0.005"/>
	</inertial>
</link>

<joint name="j_shaft" type="continuous">
	<parent link="base_link"/>
	<child link="shaft"/>
	<orogin xyz="0 0 0" rpy="0 0 0"/>
	<axis xyz="0 0 1"/>
</joint>

  <!-- ros_control plugin -->
  <gazebo>

    <plugin name="gazebo_ros_control" filename="libgazebo_ros_control.so">
      <robotNamespace>bar</robotNamespace>

      <robotSimType>gazebo_ros_control/DefaultRobotHWSim</robotSimType>
</plugin>
</gazebo>



  <!-- Base Link -->
  <gazebo reference="base_link">

  <material>Gazebo/Red</material>
  </gazebo>

  <!-- shaft-->
  <gazebo reference="shaft">

    <material>Gazebo/Green</material>
  </gazebo>

<transmission name="tran1">
    <type>transmission_interface/SimpleTransmission</type>
    <joint name="j_shaft">
      <hardwareInterface>EffortJointInterface</hardwareInterface>
    </joint>
    <actuator name="motor1">
      <hardwareInterface>EffortJointInterface</hardwareInterface>
      <mechanicalReduction>1</mechanicalReduction>
    </actuator>
  </transmission>


</robot>

